Workbook

Sheet Presentacion
A1: ='FACTURA B'!A1 -> MODELO FACTURA B
A2: ='FACTURA B'!A2 -> C.U.I.T 30-00000000-0
A3: ='FACTURA B'!A3 -> Contacto:
A4: ='FACTURA B'!A4 -> Fecha:02/02/2026
A5: ='FACTURA B'!A5 -> N° Presupuesto: P-4279
A7: ITEMS | B7: Producto | C7: Precio Unitario | D7: Cantidad | E7: Precio de Venta
A10: ='FACTURA B'!A10 -> 1 | B10: ='FACTURA B'!B10 -> 0 | C10: ='FACTURA B'!U10 -> 0 | D10: ='FACTURA B'!V10 -> 1 | E10: ='FACTURA B'!W10 -> 0 | H10: =E10*10% -> 0 | I10: =E10-H10 -> 0
A11: ='FACTURA B'!A11 -> 2 | B11: ='FACTURA B'!B11 -> 0 | C11: ='FACTURA B'!U11 -> 0 | D11: ='FACTURA B'!V11 -> 1 | E11: ='FACTURA B'!W11 -> 0
A12: ='FACTURA B'!A12 -> 3 | B12: ='FACTURA B'!B12 -> 0 | C12: ='FACTURA B'!U12 -> 0 | D12: ='FACTURA B'!V12 -> 1 | E12: ='FACTURA B'!W12 -> 0
A13: ='FACTURA B'!A13 -> 4 | B13: ='FACTURA B'!B13 -> 0 | C13: ='FACTURA B'!U13 -> 0 | D13: ='FACTURA B'!V13 -> 1 | E13: ='FACTURA B'!W13 -> 0
A14: ='FACTURA B'!A14 -> 5 | B14: ='FACTURA B'!B14 -> 0 | C14: ='FACTURA B'!U14 -> 0 | D14: ='FACTURA B'!V14 -> 1 | E14: ='FACTURA B'!W14 -> 0
A15: ='FACTURA B'!A15 -> 6 | B15: ='FACTURA B'!B15 -> 0 | C15: ='FACTURA B'!U15 -> 0 | D15: ='FACTURA B'!V15 -> 1 | E15: ='FACTURA B'!W15 -> 0
A16: ='FACTURA B'!A16 -> 7 | B16: ='FACTURA B'!B16 -> 0 | C16: ='FACTURA B'!U16 -> 0 | D16: ='FACTURA B'!V16 -> 1 | E16: ='FACTURA B'!W16 -> 0
A17: ='FACTURA B'!A17 -> 8 | B17: ='FACTURA B'!B17 -> 0 | C17: ='FACTURA B'!U17 -> 0 | D17: ='FACTURA B'!V17 -> 1 | E17: ='FACTURA B'!W17 -> 0
A18: ='FACTURA B'!A18 -> 9 | B18: ='FACTURA B'!B18 -> 0 | C18: ='FACTURA B'!U18 -> 0 | D18: ='FACTURA B'!V18 -> 1 | E18: ='FACTURA B'!W18 -> 0
A19: ='FACTURA B'!A19 -> 10 | B19: ='FACTURA B'!B19 -> 0 | C19: ='FACTURA B'!U19 -> 0 | D19: ='FACTURA B'!V19 -> 1 | E19: ='FACTURA B'!W19 -> 0
A20: ='FACTURA B'!A20 -> 11 | B20: ='FACTURA B'!B20 -> 0 | C20: ='FACTURA B'!U20 -> 0 | D20: ='FACTURA B'!V20 -> 1 | E20: ='FACTURA B'!W20 -> 0
A21: ='FACTURA B'!A21 -> 12 | B21: ='FACTURA B'!B21 -> 0 | C21: ='FACTURA B'!U21 -> 0 | D21: ='FACTURA B'!V21 -> 1 | E21: ='FACTURA B'!W21 -> 0
A22: ='FACTURA B'!A22 -> 13 | B22: ='FACTURA B'!B22 -> 0 | C22: ='FACTURA B'!U22 -> 0 | D22: ='FACTURA B'!V22 -> 1 | E22: ='FACTURA B'!W22 -> 0
... A30: ='FACTURA B'!A30 -> 21 | B30: ='FACTURA B'!B30 -> 0 | C30: ='FACTURA B'!U30 -> 0 | D30: ='FACTURA B'!V30 -> 1 | E30: ='FACTURA B'!W30 -> 0
D31: ='FACTURA B'!V32 -> Importe Total: | E31: ='FACTURA B'!W32 -> 0
C32: ='FACTURA B'!U33 -> DESCUENTO: | D32: ='FACTURA B'!V33 -> 0.1 | E32: ='FACTURA B'!W33 -> 0
D33: ='FACTURA B'!V34 -> Con Descuento: | E33: ='FACTURA B'!W34 -> 0 | F33: 0.5 | G33: =E33/2 -> 0

Sheet FACTURA B
A1: MODELO FACTURA B
A2: C.U.I.T 30-00000000-0
A3: Contacto:
A4: Fecha:02/02/2026
A5: N° Presupuesto: P-4279 | U5: =+W10 -> 0 | V5: =+U5/1.21*0.21 -> 0 | W5: =+U5+V5 -> 0
I6: =K10/C10 -> #DIV/0!
A7: ITEMS | B7: Producto | C7: COMPRA | F7: FLETE | L7: Sub Total | M7: UTILIDAD | O7: VENTA | Q7: IVA | S7: MORA | T7: INFORMAT | U7: Total Unit | V7: Cantidad | W7: Precio de Venta | X7: m3 | Y7: m3x2780 | Z7: seg xVD | AA7: total flete con iva | AB7: total Unit+IB | AC7: cantidad | AD7: total | AE7: margen total | AF7: costos grales vd | AG7: costos grales m3 | AH7: costos gral compra
D8: TOTAL PNG | E8: IVA | F8: Flete % | G8: Flete | H8: Seguro % | I8: seguro | J8: IVA | K8: Total flete | M8: Margen % | N8: Margen | O8: PRECIO NETO | Q8: IVA % | R8: VTAS | S8: IIBB
E9: 0.21 | J9: 0.21 | O9: FACT A | P9: FACT B | S9: 0.035 | T9: 0.035 | Z9: 0.008
A10: 1 | C10: 0 | D10: =C10*V10 -> 0 | E10: =D10*0.21 -> 0 | F10: 0.2 | G10: =D10*F10 -> 0 | H10: 0.009 | I10: =D10*H10 -> 0 | J10: =(G10+I10)*0.21 -> 0 | K10: =G10+I10+J10 -> 0 | L10: =D10 -> 0 | M10: 0.3 | N10: =L10*M10 -> 0 | O10: =L10+N10 -> 0 | P10: =O10+R10+S10 -> 0 | Q10: 0.21 | R10: =(O10+S10+K10)*Q10 -> 0 | S10: =+O10*0.035 -> 0 | U10: =((P10+S10+K10)/V10) -> 0 | V10: 1 | W10: =+U10*V10 -> 0 | X10: =0.6*0.7*1 -> 0.42 | Y10: =+X10*2780 -> 1167.6 | Z10: =C10*Z9 -> 0 | AA10: =+(Y10+Z10)*1.21 -> 1412.796 | AB10: =U10*1.03 -> 0 | AC10: 1 | AD10: =+AB10*AC10 -> 0 | AE10: =+N10*V10 -> 0 | AF10: =+K10*V10 -> 0 | AG10: =+AA10*AC10 -> 1412.796 | AH10: =(+C10+R10)*V10 -> 0
A11: 2 | C11: 0 | D11: =C11*V11 -> 0 | E11: =D11*0.21 -> 0 | F11: 0.2 | G11: =D11*F11 -> 0 | H11: 0.009 | I11: =D11*H11 -> 0 | J11: =(G11+I11)*0.21 -> 0 | K11: =G11+I11+J11 -> 0 | L11: =D11 -> 0 | M11: 0.3 | N11: =L11*M11 -> 0 | O11: =L11+N11 -> 0 | P11: =O11+R11+S11 -> 0 | Q11: 0.21 | R11: =(O11+S11+K11)*Q11 -> 0 | S11: =+O11*0.035 -> 0 | U11: =((P11+S11+K11)/V11) -> 0 | V11: 1 | W11: =+U11*V11 -> 0 | X11: =0.6*0.7*1 -> 0.42 | Y11: =+X11*2780 -> 1167.6 | Z11: =C11*Z9 -> 0 | AA11: =+(Y11+Z11)*1.21 -> 1412.796 | AB11: =U11*1.03 -> 0 | AC11: 1 | AD11: =+AB11*AC11 -> 0 | AF11: =+K11*V11 -> 0 | AG11: =+AA11*AC11 -> 1412.796 | AH11: =(+C11+R11)*V11 -> 0
A12: 3 | C12: 0 | D12: =C12*V12 -> 0 | E12: =D12*0.21 -> 0 | F12: 0.2 | G12: =D12*F12 -> 0 | H12: 0.009 | I12: =D12*H12 -> 0 | J12: =(G12+I12)*0.21 -> 0 | K12: =G12+I12+J12 -> 0 | L12: =D12 -> 0 | M12: 0.3 | N12: =L12*M12 -> 0 | O12: =L12+N12 -> 0 | P12: =O12+R12+S12 -> 0 | Q12: 0.21 | R12: =(O12+S12+K12)*Q12 -> 0 | S12: =+O12*0.035 -> 0 | U12: =((P12+S12+K12)/V12) -> 0 | V12: 1 | W12: =+U12*V12 -> 0 | X12: =0.6*0.7*1 -> 0.42 | Y12: =+X12*2780 -> 1167.6 | Z12: =C12*Z9 -> 0 | AA12: =+(Y12+Z12)*1.21 -> 1412.796 | AB12: =U12*1.03 -> 0 | AC12: 1 | AD12: =+AB12*AC12 -> 0 | AF12: =+K12*V12 -> 0 | AG12: =+AA12*AC12 -> 1412.796 | AH12: =(+C12+R12)*V12 -> 0
A13: 4 | C13: 0 | D13: =C13*V13 -> 0 | E13: =D13*0.21 -> 0 | F13: 0.2 | G13: =D13*F13 -> 0 | H13: 0.009 | I13: =D13*H13 -> 0 | J13: =(G13+I13)*0.21 -> 0 | K13: =G13+I13+J13 -> 0 | L13: =D13 -> 0 | M13: 0.3 | N13: =L13*M13 -> 0 | O13: =L13+N13 -> 0 | P13: =O13+R13+S13 -> 0 | Q13: 0.21 | R13: =(O13+S13+K13)*Q13 -> 0 | S13: =+O13*0.035 -> 0 | U13: =((P13+S13+K13)/V13) -> 0 | V13: 1 | W13: =+U13*V13 -> 0 | X13: =0.6*0.7*1 -> 0.42 | Y13: =+X13*2780 -> 1167.6 | Z13: =C13*Z9 -> 0 | AA13: =+(Y13+Z13)*1.21 -> 1412.796 | AB13: =U13*1.03 -> 0 | AC13: 1 | AD13: =+AB13*AC13 -> 0 | AE13: =+N13*V13 -> 0 | AF13: =+K13*V13 -> 0 | AG13: =+AA13*AC13 -> 1412.796 | AH13: =(+C13+R13)*V13 -> 0
A14: 5 | C14: 0 | D14: =C14*V14 -> 0 | E14: =D14*0.21 -> 0 | F14: 0.2 | G14: =D14*F14 -> 0 | H14: 0.009 | I14: =D14*H14 -> 0 | J14: =(G14+I14)*0.21 -> 0 | K14: =G14+I14+J14 -> 0 | L14: =D14 -> 0 | M14: 0.3 | N14: =L14*M14 -> 0 | O14: =L14+N14 -> 0 | P14: =O14+R14+S14 -> 0 | Q14: 0.21 | R14: =(O14+S14+K14)*Q14 -> 0 | S14: =+O14*0.035 -> 0 | U14: =((P14+S14+K14)/V14) -> 0 | V14: 1 | W14: =+U14*V14 -> 0 | X14: =0.6*0.7*1 -> 0.42 | Y14: =+X14*2780 -> 1167.6 | Z14: =C14*Z9 -> 0 | AA14: =+(Y14+Z14)*1.21 -> 1412.796 | AB14: =U14*1.03 -> 0 | AC14: 1 | AD14: =+AB14*AC14 -> 0 | AF14: =+K14*V14 -> 0 | AG14: =+AA14*AC14 -> 1412.796 | AH14: =(+C14+R14)*V14 -> 0
A15: 6 | C15: 0 | D15: =C15*V15 -> 0 | E15: =D15*0.21 -> 0 | F15: 0.2 | G15: =D15*F15 -> 0 | H15: 0.009 | I15: =D15*H15 -> 0 | J15: =(G15+I15)*0.21 -> 0 | K15: =G15+I15+J15 -> 0 | L15: =D15 -> 0 | M15: 0.3 | N15: =L15*M15 -> 0 | O15: =L15+N15 -> 0 | P15: =O15+R15+S15 -> 0 | Q15: 0.21 | R15: =(O15+S15+K15)*Q15 -> 0 | S15: =+O15*0.035 -> 0 | U15: =((P15+S15+K15)/V15) -> 0 | V15: 1 | W15: =+U15*V15 -> 0 | X15: =0.6*0.7*1 -> 0.42 | Y15: =+X15*2780 -> 1167.6 | Z15: =C15*Z9 -> 0 | AA15: =+(Y15+Z15)*1.21 -> 1412.796 | AB15: =U15*1.03 -> 0 | AC15: 1 | AD15: =+AB15*AC15 -> 0 | AF15: =+K15*V15 -> 0 | AG15: =+AA15*AC15 -> 1412.796 | AH15: =(+C15+R15)*V15 -> 0
A16: 7 | C16: 0 | D16: =C16*V16 -> 0 | E16: =D16*0.21 -> 0 | F16: 0.2 | G16: =D16*F16 -> 0 | H16: 0.009 | I16: =D16*H16 -> 0 | J16: =(G16+I16)*0.21 -> 0 | K16: =G16+I16+J16 -> 0 | L16: =D16 -> 0 | M16: 0.3 | N16: =L16*M16 -> 0 | O16: =L16+N16 -> 0 | P16: =O16+R16+S16 -> 0 | Q16: 0.21 | R16: =(O16+S16+K16)*Q16 -> 0 | S16: =+O16*0.035 -> 0 | U16: =((P16+S16+K16)/V16) -> 0 | V16: 1 | W16: =+U16*V16 -> 0 | X16: =0.6*0.7*1 -> 0.42 | Y16: =+X16*2780 -> 1167.6 | Z16: =C16*Z9 -> 0 | AA16: =+(Y16+Z16)*1.21 -> 1412.796 | AB16: =U16*1.03 -> 0 | AC16: 1 | AD16: =+AB16*AC16 -> 0 | AE16: =+N16*V16 -> 0 | AF16: =+K16*V16 -> 0 | AG16: =+AA16*AC16 -> 1412.796 | AH16: =(+C16+R16)*V16 -> 0
A17: 8 | C17: 0 | D17: =C17*V17 -> 0 | E17: =D17*0.21 -> 0 | F17: 0.2 | G17: =D17*F17 -> 0 | H17: 0.009 | I17: =D17*H17 -> 0 | J17: =(G17+I17)*0.21 -> 0 | K17: =G17+I17+J17 -> 0 | L17: =D17 -> 0 | M17: 0.3 | N17: =L17*M17 -> 0 | O17: =L17+N17 -> 0 | P17: =O17+R17+S17 -> 0 | Q17: 0.21 | R17: =(O17+S17+K17)*Q17 -> 0 | S17: =+O17*0.035 -> 0 | U17: =((P17+S17+K17)/V17) -> 0 | V17: 1 | W17: =+U17*V17 -> 0 | X17: =0.6*0.7*1 -> 0.42 | Y17: =+X17*2780 -> 1167.6 | Z17: =C17*Z9 -> 0 | AA17: =+(Y17+Z17)*1.21 -> 1412.796 | AB17: =U17*1.03 -> 0 | AC17: 1 | AD17: =+AB17*AC17 -> 0 | AE17: =+N17*V17 -> 0 | AF17: =+K17*V17 -> 0 | AG17: =+AA17*AC17 -> 1412.796 | AH17: =(+C17+R17)*V17 -> 0
A18: 9 | C18: 0 | D18: =C18*V18 -> 0 | E18: =D18*0.21 -> 0 | F18: 0.2 | G18: =D18*F18 -> 0 | H18: 0.009 | I18: =D18*H18 -> 0 | J18: =(G18+I18)*0.21 -> 0 | K18: =G18+I18+J18 -> 0 | L18: =D18 -> 0 | M18: 0.3 | N18: =L18*M18 -> 0 | O18: =L18+N18 -> 0 | P18: =O18+R18+S18 -> 0 | Q18: 0.21 | R18: =(O18+S18+K18)*Q18 -> 0 | S18: =+O18*0.035 -> 0 | U18: =((P18+S18+K18)/V18) -> 0 | V18: 1 | W18: =+U18*V18 -> 0 | X18: =0.6*0.7*1 -> 0.42 | Y18: =+X18*2780 -> 1167.6 | Z18: =C18*Z9 -> 0 | AA18: =+(Y18+Z18)*1.21 -> 1412.796 | AB18: =U18*1.03 -> 0 | AC18: 1 | AD18: =+AB18*AC18 -> 0 | AE18: =+N18*V18 -> 0 | AF18: =+K18*V18 -> 0 | AG18: =+AA18*AC18 -> 1412.796 | AH18: =(+C18+R18)*V18 -> 0
A19: 10 | C19: 0 | D19: =C19*V19 -> 0 | E19: =D19*0.21 -> 0 | F19: 0.2 | G19: =D19*F19 -> 0 | H19: 0.009 | I19: =D19*H19 -> 0 | J19: =(G19+I19)*0.21 -> 0 | K19: =G19+I19+J19 -> 0 | L19: =D19 -> 0 | M19: 0.3 | N19: =L19*M19 -> 0 | O19: =L19+N19 -> 0 | P19: =O19+R19+S19 -> 0 | Q19: 0.21 | R19: =(O19+S19+K19)*Q19 -> 0 | S19: =+O19*0.035 -> 0 | U19: =((P19+S19+K19)/V19) -> 0 | V19: 1 | W19: =+U19*V19 -> 0 | X19: =0.6*0.7*1 -> 0.42 | Y19: =+X19*2780 -> 1167.6 | Z19: =C19*Z9 -> 0 | AA19: =+(Y19+Z19)*1.21 -> 1412.796 | AB19: =U19*1.03 -> 0 | AC19: 1 | AD19: =+AB19*AC19 -> 0 | AE19: =+N19*V19 -> 0 | AF19: =+K19*V19 -> 0 | AG19: =+AA19*AC19 -> 1412.796 | AH19: =(+C19+R19)*V19 -> 0
A20: 11 | C20: 0 | D20: =C20*V20 -> 0 | E20: =D20*0.21 -> 0 | F20: 0.2 | G20: =D20*F20 -> 0 | H20: 0.009 | I20: =D20*H20 -> 0 | J20: =(G20+I20)*0.21 -> 0 | K20: =G20+I20+J20 -> 0 | L20: =D20 -> 0 | M20: 0.3 | N20: =L20*M20 -> 0 | O20: =L20+N20 -> 0 | P20: =O20+R20+S20 -> 0 | Q20: 0.21 | R20: =(O20+S20+K20)*Q20 -> 0 | S20: =+O20*0.035 -> 0 | U20: =((P20+S20+K20)/V20) -> 0 | V20: 1 | W20: =+U20*V20 -> 0 | X20: =0.6*0.7*1 -> 0.42 | Y20: =+X20*2780 -> 1167.6 | Z20: =C20*Z9 -> 0 | AA20: =+(Y20+Z20)*1.21 -> 1412.796 | AB20: =U20*1.03 -> 0 | AC20: 1 | AD20: =+AB20*AC20 -> 0 | AE20: =+N20*V20 -> 0 | AF20: =+K20*V20 -> 0 | AG20: =+AA20*AC20 -> 1412.796 | AH20: =(+C20+R20)*V20 -> 0
A21: 12 | C21: 0 | D21: =C21*V21 -> 0 | E21: =D21*0.21 -> 0 | F21: 0.2 | G21: =D21*F21 -> 0 | H21: 0.009 | I21: =D21*H21 -> 0 | J21: =(G21+I21)*0.21 -> 0 | K21: =G21+I21+J21 -> 0 | L21: =D21 -> 0 | M21: 0.3 | N21: =L21*M21 -> 0 | O21: =L21+N21 -> 0 | P21: =O21+R21+S21 -> 0 | Q21: 0.21 | R21: =(O21+S21+K21)*Q21 -> 0 | S21: =+O21*0.035 -> 0 | U21: =((P21+S21+K21)/V21) -> 0 | V21: 1 | W21: =+U21*V21 -> 0 | X21: =0.6*0.7*1 -> 0.42 | Y21: =+X21*2780 -> 1167.6 | Z21: =C21*Z9 -> 0 | AA21: =+(Y21+Z21)*1.21 -> 1412.796 | AB21: =U21*1.03 -> 0 | AC21: 1 | AD21: =+AB21*AC21 -> 0 | AE21: =+N21*V21 -> 0 | AF21: =+K21*V21 -> 0 | AG21: =+AA21*AC21 -> 1412.796 | AH21: =(+C21+R21)*V21 -> 0
A22: 13 | C22: 0 | D22: =C22*V22 -> 0 | E22: =D22*0.21 -> 0 | F22: 0.2 | G22: =D22*F22 -> 0 | H22: 0.009 | I22: =D22*H22 -> 0 | J22: =(G22+I22)*0.21 -> 0 | K22: =G22+I22+J22 -> 0 | L22: =D22 -> 0 | M22: 0.3 | N22: =L22*M22 -> 0 | O22: =L22+N22 -> 0 | P22: =O22+R22+S22 -> 0 | Q22: 0.21 | R22: =(O22+S22+K22)*Q22 -> 0 | S22: =+O22*0.035 -> 0 | U22: =((P22+S22+K22)/V22) -> 0 | V22: 1 | W22: =+U22*V22 -> 0 | X22: =0.6*0.7*1 -> 0.42 | Y22: =+X22*2780 -> 1167.6 | Z22: =C22*Z9 -> 0 | AA22: =+(Y22+Z22)*1.21 -> 1412.796 | AB22: =U22*1.03 -> 0 | AC22: 1 | AD22: =+AB22*AC22 -> 0 | AE22: =+N22*V22 -> 0 | AF22: =+K22*V22 -> 0 | AG22: =+AA22*AC22 -> 1412.796 | AH22: =(+C22+R22)*V22 -> 0
A23: 14 | C23: 0 | D23: =C23*V23 -> 0 | E23: =D23*0.21 -> 0 | F23: 0.2 | G23: =D23*F23 -> 0 | H23: 0.009 | I23: =D23*H23 -> 0 | J23: =(G23+I23)*0.21 -> 0 | K23: =G23+I23+J23 -> 0 | L23: =D23 -> 0 | M23: 0.3 | N23: =L23*M23 -> 0 | O23: =L23+N23 -> 0 | P23: =O23+R23+S23 -> 0 | Q23: 0.21 | R23: =(O23+S23+K23)*Q23 -> 0 | S23: =+O23*0.035 -> 0 | U23: =((P23+S23+K23)/V23) -> 0 | V23: 1 | W23: =+U23*V23 -> 0 | X23: =0.6*0.7*1 -> 0.42 | Y23: =+X23*2780 -> 1167.6 | Z23: =C23*Z9 -> 0 | AA23: =+(Y23+Z23)*1.21 -> 1412.796 | AB23: =U23*1.03 -> 0 | AC23: 1 | AD23: =+AB23*AC23 -> 0 | AE23: =+N23*V23 -> 0 | AF23: =+K23*V23 -> 0 | AG23: =+AA23*AC23 -> 1412.796 | AH23: =(+C23+R23)*V23 -> 0
A24: 15 | C24: 0 | D24: =C24*V24 -> 0 | E24: =D24*0.21 -> 0 | F24: 0.2 | G24: =D24*F24 -> 0 | H24: 0.009 | I24: =D24*H24 -> 0 | J24: =(G24+I24)*0.21 -> 0 | K24: =G24+I24+J24 -> 0 | L24: =D24 -> 0 | M24: 0.3 | N24: =L24*M24 -> 0 | O24: =L24+N24 -> 0 | P24: =O24+R24+S24 -> 0 | Q24: 0.21 | R24: =(O24+S24+K24)*Q24 -> 0 | S24: =+O24*0.035 -> 0 | U24: =((P24+S24+K24)/V24) -> 0 | V24: 1 | W24: =+U24*V24 -> 0 | X24: =0.6*0.7*1 -> 0.42 | Y24: =+X24*2780 -> 1167.6 | Z24: =C24*Z9 -> 0 | AA24: =+(Y24+Z24)*1.21 -> 1412.796 | AB24: =U24*1.03 -> 0 | AC24: 1 | AD24: =+AB24*AC24 -> 0 | AE24: =+N24*V24 -> 0 | AF24: =+K24*V24 -> 0 | AG24: =+AA24*AC24 -> 1412.796 | AH24: =(+C24+R24)*V24 -> 0
A25: 16 | C25: 0 | D25: =C25*V25 -> 0 | E25: =D25*0.21 -> 0 | F25: 0.2 | G25: =D25*F25 -> 0 | H25: 0.009 | I25: =D25*H25 -> 0 | J25: =(G25+I25)*0.21 -> 0 | K25: =G25+I25+J25 -> 0 | L25: =D25 -> 0 | M25: 0.3 | N25: =L25*M25 -> 0 | O25: =L25+N25 -> 0 | P25: =O25+R25+S25 -> 0 | Q25: 0.21 | R25: =(O25+S25+K25)*Q25 -> 0 | S25: =+O25*0.035 -> 0 | U25: =((P25+S25+K25)/V25) -> 0 | V25: 1 | W25: =+U25*V25 -> 0 | X25: =0.6*0.7*1 -> 0.42 | Y25: =+X25*2780 -> 1167.6 | Z25: =C25*Z9 -> 0 | AA25: =+(Y25+Z25)*1.21 -> 1412.796 | AB25: =U25*1.03 -> 0 | AC25: 1 | AD25: =+AB25*AC25 -> 0 | AE25: =+N25*V25 -> 0 | AF25: =+K25*V25 -> 0 | AG25: =+AA25*AC25 -> 1412.796 | AH25: =(+C25+R25)*V25 -> 0
A26: 17 | C26: 0 | D26: =C26*V26 -> 0 | E26: =D26*0.21 -> 0 | F26: 0.2 | G26: =D26*F26 -> 0 | H26: 0.009 | I26: =D26*H26 -> 0 | J26: =(G26+I26)*0.21 -> 0 | K26: =G26+I26+J26 -> 0 | L26: =D26 -> 0 | M26: 0.3 | N26: =L26*M26 -> 0 | O26: =L26+N26 -> 0 | P26: =O26+R26+S26 -> 0 | Q26: 0.21 | R26: =(O26+S26+K26)*Q26 -> 0 | S26: =+O26*0.035 -> 0 | U26: =((P26+S26+K26)/V26) -> 0 | V26: 1 | W26: =+U26*V26 -> 0 | X26: =0.6*0.7*1 -> 0.42 | Y26: =+X26*2780 -> 1167.6 | Z26: =C26*Z9 -> 0 | AA26: =+(Y26+Z26)*1.21 -> 1412.796 | AB26: =U26*1.03 -> 0 | AC26: 1 | AD26: =+AB26*AC26 -> 0 | AE26: =+N26*V26 -> 0 | AF26: =+K26*V26 -> 0 | AG26: =+AA26*AC26 -> 1412.796 | AH26: =(+C26+R26)*V26 -> 0
A27: 18 | C27: 0 | D27: =C27*V27 -> 0 | E27: =D27*0.21 -> 0 | F27: 0.2 | G27: =D27*F27 -> 0 | H27: 0.009 | I27: =D27*H27 -> 0 | J27: =(G27+I27)*0.21 -> 0 | K27: =G27+I27+J27 -> 0 | L27: =D27 -> 0 | M27: 0.3 | N27: =L27*M27 -> 0 | O27: =L27+N27 -> 0 | P27: =O27+R27+S27 -> 0 | Q27: 0.21 | R27: =(O27+S27+K27)*Q27 -> 0 | S27: =+O27*0.035 -> 0 | U27: =((P27+S27+K27)/V27) -> 0 | V27: 1 | W27: =+U27*V27 -> 0 | X27: =0.6*0.7*1 -> 0.42 | Y27: =+X27*2780 -> 1167.6 | Z27: =C27*Z9 -> 0 | AA27: =+(Y27+Z27)*1.21 -> 1412.796 | AB27: =U27*1.03 -> 0 | AC27: 1 | AD27: =+AB27*AC27 -> 0 | AE27: =+N27*V27 -> 0 | AF27: =+K27*V27 -> 0 | AG27: =+AA27*AC27 -> 1412.796 | AH27: =(+C27+R27)*V27 -> 0
A28: 19 | C28: 0 | D28: =C28*V28 -> 0 | E28: =D28*0.21 -> 0 | F28: 0.2 | G28: =D28*F28 -> 0 | H28: 0.009 | I28: =D28*H28 -> 0 | J28: =(G28+I28)*0.21 -> 0 | K28: =G28+I28+J28 -> 0 | L28: =D28 -> 0 | M28: 0.3 | N28: =L28*M28 -> 0 | O28: =L28+N28 -> 0 | P28: =O28+R28+S28 -> 0 | Q28: 0.21 | R28: =(O28+S28+K28)*Q28 -> 0 | S28: =+O28*0.035 -> 0 | U28: =((P28+S28+K28)/V28) -> 0 | V28: 1 | W28: =+U28*V28 -> 0 | X28: =0.6*0.7*1 -> 0.42 | Y28: =+X28*2780 -> 1167.6 | Z28: =C28*Z9 -> 0 | AA28: =+(Y28+Z28)*1.21 -> 1412.796 | AB28: =U28*1.03 -> 0 | AC28: 1 | AD28: =+AB28*AC28 -> 0 | AE28: =+N28*V28 -> 0 | AF28: =+K28*V28 -> 0 | AG28: =+AA28*AC28 -> 1412.796 | AH28: =(+C28+R28)*V28 -> 0
A29: 20 | C29: 0 | D29: =C29*V29 -> 0 | E29: =D29*0.21 -> 0 | F29: 0.2 | G29: =D29*F29 -> 0 | H29: 0.009 | I29: =D29*H29 -> 0 | J29: =(G29+I29)*0.21 -> 0 | K29: =G29+I29+J29 -> 0 | L29: =D29 -> 0 | M29: 0.3 | N29: =L29*M29 -> 0 | O29: =L29+N29 -> 0 | P29: =O29+R29+S29 -> 0 | Q29: 0.21 | R29: =(O29+S29+K29)*Q29 -> 0 | S29: =+O29*0.035 -> 0 | U29: =((P29+S29+K29)/V29) -> 0 | V29: 1 | W29: =+U29*V29 -> 0 | X29: =0.6*0.7*1 -> 0.42 | Y29: =+X29*2780 -> 1167.6 | Z29: =C29*Z9 -> 0 | AA29: =+(Y29+Z29)*1.21 -> 1412.796 | AB29: =U29*1.03 -> 0 | AC29: 1 | AD29: =+AB29*AC29 -> 0 | AF29: =+K29*V29 -> 0 | AG29: =+AA29*AC29 -> 1412.796 | AH29: =(+C29+R29)*V29 -> 0
A30: 21 | C30: 0 | D30: =C30*V30 -> 0 | E30: =D30*0.21 -> 0 | F30: 0.2 | G30: =D30*F30 -> 0 | H30: 0.009 | I30: =D30*H30 -> 0 | J30: =(G30+I30)*0.21 -> 0 | K30: =G30+I30+J30 -> 0 | L30: =D30 -> 0 | M30: 0.3 | N30: =L30*M30 -> 0 | O30: =L30+N30 -> 0 | P30: =O30+R30+S30 -> 0 | Q30: 0.21 | R30: =(O30+S30+K30)*Q30 -> 0 | S30: =+O30*0.035 -> 0 | U30: =((P30+S30+K30)/V30) -> 0 | V30: 1 | W30: =+U30*V30 -> 0 | X30: =0.6*0.7*1 -> 0.42 | Y30: =+X30*2780 -> 1167.6 | Z30: =C30*Z9 -> 0 | AA30: =+(Y30+Z30)*1.21 -> 1412.796 | AB30: =U30*1.03 -> 0 | AC30: 1 | AD30: =+AB30*AC30 -> 0 | AE30: =+N30*V30 -> 0 | AF30: =+K30*V30 -> 0 | AG30: =+AA30*AC30 -> 1412.796 | AH30: =(+C30+R30)*V30 -> 0
C31: =SUM(C10:C30) -> 0 | D31: =SUM(D10:D30) -> 0 | E31: =SUM(E10:E30) -> 0 | J31: =SUM(J10:J30) -> 0 | K31: =SUM(K10:K30) -> 0 | L31: =SUM(L10:L30) -> 0 | N31: =SUM(N10:N30) -> 0 | O31: =SUM(O10:O30) -> 0 | P31: =SUM(P10:P30) -> 0 | R31: =SUM(R10:R30) -> 0 | S31: =W32*0.035 -> 0 | U31: =SUM(U10:U30) -> 0 | AE31: =SUM(AE10:AE30) -> 0
Q32: Dto: | R32: =R31*V33 -> 0 | S32: =S31*V33 -> 0 | V32: Importe Total: | W32: =SUM(W10:W30) -> 0
N33: Con Descuento: | P33: Con Descuento: | U33: DESCUENTO: | V33: 0.1 | W33: =W32*V33 -> 0
C34: COMPRA | D34: =D31 -> 0 | G34: IVA VENTAS | H34: =R31 -> 0 | J34: VENTA | K34: =W32 -> 0 | M34: VENTA | N34: =W34 -> 0 | P34: iva | Q34: =+W34*0.21 -> 0 | V34: Con Descuento: | W34: =W32-W33 -> 0
C35: MARGEN | D35: =N31 -> 0 | G35: IVA COMPRAS | H35: =+E31+J31 -> 0 | J35: COSTO | K35: =D31+E31+S31+K31+H36 -> 0 | M35: COSTO | N35: =K35-R32-S32 -> 0 | P35: iibb | Q35: =+W34*0.035 -> 0
C36: FLETE | D36: =K31 -> 0 | G36: IVA A PAGAR | H36: =+H34-H35 -> 0 | J36: GCIA | K36: =K34-K35 -> 0 | M36: GCIA | N36: =N34-N35 -> 0
C37: IIBB | D37: =S31 -> 0 | J37: EN % | K37: =K36/K35 -> #DIV/0! | M37: EN % | N37: =N36/N35 -> #DIV/0! | P37: IVA VENTAS | Q37: =Q34 -> 0
C38: SUBTOTAL | D38: =SUM(D34:D37) -> 0 | P38: IVA COMPRAS | Q38: =H35 -> 0
C39: IVA VENTAS | D39: =R31 -> 0 | G39: =H36/0.21 -> 0 | J39: ROI | K39: =(K34-D38)/D38 -> #DIV/0! | P39: IVA A PAGAR | Q39: =+Q37-Q38 -> 0
C40: PRECIO FINAL | D40: =SUM(D38:D39) -> 0 | J40: RAE | K40: =K36/(K35) -> #DIV/0!
...
